Workbook

Sheet NWC
A1: Column1 | B1: 2020 | C1: 2021 | D1: 2022 | E1: 2023 | F1: 2024 | G1: 2024Q4-2025Q3
A2: Zmiana stanu zapasów | B2: -251.152 | C2: -498.316 | D2: -605.315 | E2: -660.081 | F2: -424.123 | G2: 21.382
A3: Zmiana stanu należności | B3: -43.201 | C3: -24.88 | D3: 14.54 | E3: -54.668 | F3: -55.966 | G3: 245.129
A4: Zmiana stanu rozliczeń międzyokresowych | B4: 13.06 | C4: 14.733 | D4: 25.226 | E4: 42.634 | F4: 0 | G4: 0
A5: Zmiana stanu zobowiązań | B5: 197.916 | C5: 728.449 | D5: 366.502 | E5: 42.634 | F5: 1126.352 | G5: -202.932
A6: Zmiana NWC | B6: =-SUM(B2:B5) -> 83.377 | C6: =-SUM(C2:C5) -> -219.986 | D6: =-SUM(D2:D5) -> 199.047 | E6: =-SUM(E2:E5) -> 629.481 | F6: =-SUM(F2:F5) -> -646.263 | G6: =-SUM(G2:G5) -> -63.579

Sheet CF
A1: Column1 | B1: 2020 (gru 20) | C1: 2021 (gru 21) | D1: 2022 (gru 22) | E1: 2023 (gru 23) | F1: 2024 (gru 24) | G1: O4K (wrz 25)* | H1: Kolumna1
A2: Przepływy pieniężne z działalności operacyjnej | B2: 819 922 | C2: 1 326 331 | D2: 1 253 422 | E2: 1 771 540 | F2: 2 557 453 | G2: 2 476 835
A3: Amortyzacja | B3: 198 146 | C3: 247 343 | D3: 300 129 | E3: 356 828 | F3: 409 179 | G3: 479 009
A4: Przepływy pieniężne z działalności inwestycyjnej | B4: -1 000 136 | C4: -1 330 728 | D4: -1 434 563 | E4: -1 158 256 | F4: -1 596 909 | G4: -1 997 353
A5: CAPEX (niematerialne i rzeczowe) | B5: 1 002 025 | C5: 1 335 604 | D5: 1 445 905 | E5: 1 172 863 | F5: 1 561 914 | G5: 2 007 180
A6: Przepływy pieniężne z działalności finansowej | B6: 265 912 | C6: -57 406 | D6: 145 244 | E6: -777 613 | F6: -287 911 | G6: -478 296
A7: Emisja akcji | B7: 0 | C7: 0 | D7: 0 | E7: 0 | F7: 0 | G7: 0
A8: Dywidenda | B8: 0 | C8: 0 | D8: 0 | E8: 0 | F8: 0 | G8: 0
A9: Skup akcji
A10: Płatności z tytułu umów leasingu
A11: Przepływy pieniężne razem | B11: 85 698 | C11: -61 803 | D11: -35 897 | E11: -164 329 | F11: 672 633 | G11: 1 186
A12: Free Cash Flow
A14: Column1 | B14: 2020 (gru 20) | C14: 2021 (gru 21) | D14: 2022 (gru 22) | E14: 2023 (gru 23) | F14: 2024 (gru 24) | G14: O4K (wrz 25)* | H14: Kolumna1
A15: Przepływy pieniężne z działalności operacyjnej | B15: =B2/1000 -> 819.922 | C15: =C2/1000 -> 1326.331 | D15: =D2/1000 -> 1253.422 | E15: =E2/1000 -> 1771.54 | F15: =F2/1000 -> 2557.453 | G15: =G2/1000 -> 2476.835
A16: Amortyzacja | B16: =B3/1000 -> 198.146 | C16: =C3/1000 -> 247.343 | D16: =D3/1000 -> 300.129 | E16: =E3/1000 -> 356.828 | F16: =F3/1000 -> 409.179 | G16: =G3/1000 -> 479.009
A17: Przepływy pieniężne z działalności inwestycyjnej | B17: =B4/1000 -> -1000.136 | C17: =C4/1000 -> -1330.728 | D17: =D4/1000 -> -1434.563 | E17: =E4/1000 -> -1158.256 | F17: =F4/1000 -> -1596.909 | G17: =G4/1000 -> -1997.353
A18: CAPEX (niematerialne i rzeczowe) | B18: =B5/1000 -> 1002.025 | C18: =C5/1000 -> 1335.604 | D18: =D5/1000 -> 1445.905 | E18: =E5/1000 -> 1172.863 | F18: =F5/1000 -> 1561.914 | G18: =G5/1000 -> 2007.18
A19: Przepływy pieniężne z działalności finansowej | B19: =B6/1000 -> 265.912 | C19: =C6/1000 -> -57.406 | D19: =D6/1000 -> 145.244 | E19: =E6/1000 -> -777.613 | F19: =F6/1000 -> -287.911 | G19: =G6/1000 -> -478.296
A20: Emisja akcji | B20: =B7/1000 -> 0 | C20: =C7/1000 -> 0 | D20: =D7/1000 -> 0 | E20: =E7/1000 -> 0 | F20: =F7/1000 -> 0 | G20: =G7/1000 -> 0
A21: Dywidenda | B21: =B8/1000 -> 0 | C21: =C8/1000 -> 0 | D21: =D8/1000 -> 0 | E21: =E8/1000 -> 0 | F21: =F8/1000 -> 0 | G21: =G8/1000 -> 0
A22: Skup akcji | B22: =B9/1000 -> #VALUE! | C22: =C9/1000 -> #VALUE! | D22: =D9/1000 -> #VALUE! | E22: =E9/1000 -> #VALUE! | F22: =F9/1000 -> #VALUE! | G22: =G9/1000 -> #VALUE!
A23: Płatności z tytułu umów leasingu | B23: =B10/1000 -> #VALUE! | C23: =C10/1000 -> #VALUE! | D23: =D10/1000 -> #VALUE! | E23: =E10/1000 -> #VALUE! | F23: =F10/1000 -> #VALUE! | G23: =G10/1000 -> #VALUE!
A24: Przepływy pieniężne razem | B24: =B11/1000 -> 85.698 | C24: =C11/1000 -> -61.803 | D24: =D11/1000 -> -35.897 | E24: =E11/1000 -> -164.329 | F24: =F11/1000 -> 672.633 | G24: =G11/1000 -> 1.186
A25: Free Cash Flow | B25: =B12/1000 -> #VALUE! | C25: =C12/1000 -> #VALUE! | D25: =D12/1000 -> #VALUE! | E25: =E12/1000 -> #VALUE! | F25: =F12/1000 -> #VALUE! | G25: =G12/1000 -> #VALUE!

Sheet ETR
A1: Column1 | B1: 2020 | C1: 2021 | D1: 2022 | E1: 2023 | F1: 2024
A2: Zysk brutto | B2: 789000 | C2: 978409 | D2: 1401618 | E2: 1738981 | F2: 1793563
A3: Podatek dochodowy | B3: -145083 | C3: -173106 | D3: -269531 | E3: -333654 | F3: -287834
A4: ETR | B4: =ABS(B3/B2) -> 0.18388213 | C4: =ABS(C3/C2) -> 0.17692601 | D4: =ABS(D3/D2) -> 0.1922999 | E4: =ABS(E3/E2) -> 0.19186754 | F4: =ABS(F3/F2) -> 0.16048168 | H4: =AVERAGE(ETR[[#This Row],[2020]:[2024]]) -> 0.18109145
H5: Stawka została przyjęta na poziomie ustawowym ze względu na stabilność historyczną ETR

Sheet RZiS
A1: Column1 | B1: 2020 (gru 20) | C1: 2021 (gru 21) | D1: 2022 (gru 22) | E1: 2023 (gru 23) | F1: 2024 (gru 24) | G1: O4K (wrz 25)*
A2: Przychody ze sprzedaży | B2: 10 125 815 | C2: 13 362 012 | D2: 19 801 622 | E2: 25 666 255 | F2: 29 273 792 | G2: 32 490 262
A3: Techniczny koszt wytworzenia produkcji sprzedanej | B3: 7 521 986 | C3: 10 038 342 | D3: 15 038 630 | E3: 19 741 459 | F3: 22 463 233 | G3: 24 779 603
A4: Koszty sprzedaży | B4: 1 668 084 | C4: 2 181 963 | D4: 3 080 061 | E4: 3 878 421 | F4: 4 678 717 | G4: 5 381 475
A5: Koszty ogólnego zarządu | B5: 99 783 | C5: 117 285 | D5: 143 217 | E5: 173 736 | F5: 233 653 | G5: 258 114
A6: Zysk ze sprzedaży | B6: 835 962 | C6: 1 024 422 | D6: 1 539 714 | E6: 1 872 639 | F6: 1 898 189 | G6: 2 071 070
A7: Pozostałe przychody operacyjne | B7: 7 598 | C7: 14 364 | D7: 16 282 | E7: 13 477 | F7: 24 185 | G7: 33 685
A8: Pozostałe koszty operacyjne | B8: 5 701 | C8: 14 793 | D8: 18 177 | E8: 10 261 | F8: 14 044 | G8: 19 557
A9: Zysk operacyjny (EBIT) | B9: 837 859 | C9: 1 023 993 | D9: 1 537 819 | E9: 1 875 855 | F9: 1 908 330 | G9: 2 085 198
A10: Przychody finansowe | B10: 3 237 | C10: 1 119 | D10: 5 092 | E10: 10 442 | F10: 6 657 | G10: 8 553
A11: Koszty finansowe | B11: 52 096 | C11: 46 703 | D11: 141 293 | E11: 147 316 | F11: 121 424 | G11: 126 247
A12: Pozostałe przychody (koszty) | B12: 0 | C12: 0 | D12: 0 | E12: 0 | F12: 0 | G12: 0
... A21: Column1 | B21: 2020 (gru 20) | C21: 2021 (gru 21) | D21: 2022 (gru 22) | E21: 2023 (gru 23) | F21: 2024 (gru 24) | G21: O4K (wrz 25)*
A22: Przychody ze sprzedaży | B22: 10125.815 | C22: 13362.012 | D22: 19801.622 | E22: 25666.255 | F22: 29273.792 | G22: 32490.262
A23: Techniczny koszt wytworzenia produkcji sprzedanej | B23: 7521.986 | C23: 10038.342 | D23: 15038.63 | E23: 19741.459 | F23: 22463.233 | G23: 24779.603
A24: Koszty sprzedaży | B24: 1668.084 | C24: 2181.963 | D24: 3080.061 | E24: 3878.421 | F24: 4678.717 | G24: 5381.475
A25: Koszty ogólnego zarządu | B25: 99.783 | C25: 117.285 | D25: 143.217 | E25: 173.736 | F25: 233.653 | G25: 258.114
A26: Zysk ze sprzedaży | B26: 835.962 | C26: 1024.422 | D26: 1539.714 | E26: 1872.639 | F26: 1898.189 | G26: 2071.07
A27: Pozostałe przychody operacyjne | B27: 7.598 | C27: 14.364 | D27: 16.282 | E27: 13.477 | F27: 24.185 | G27: 33.685
A28: Pozostałe koszty operacyjne | B28: 5.701 | C28: 14.793 | D28: 18.177 | E28: 10.261 | F28: 14.044 | G28: 19.557
A29: Zysk operacyjny (EBIT) | B29: 837.859 | C29: 1023.993 | D29: 1537.819 | E29: 1875.855 | F29: 1908.33 | G29: 2085.198
A30: Przychody finansowe | B30: 3.237 | C30: 1.119 | D30: 5.092 | E30: 10.442 | F30: 6.657 | G30: 8.553
A31: Koszty finansowe | B31: 52.096 | C31: 46.703 | D31: 141.293 | E31: 147.316 | F31: 121.424 | G31: 126.247
A32: Pozostałe przychody (koszty) | B32: 0 | C32: 0 | D32: 0 | E32: 0 | F32: 0 | G32: 0
A33: Zysk z działalności gospodarczej | B33: 789 | C33: 978.409 | D33: 1401.618 | E33: 1738.981 | F33: 1793.563 | G33: 1967.504
... A38: Zysk netto akcjonariuszy jednostki dominującej | B38: 643.917 | C38: 805.303 | D38: 1132.087 | E38: 1405.327 | F38: 1504.98 | G38: 1614.283
G41: Ebitda | H41: market capit | I41: Zysk netto | J41: cena
F42: Dino | G42: 1563955000 | H42: =Valuation!B3*1000000 -> 38588544000 | I42: 1191047000 | J42: 39.63
F43: Jeronimo Martins | G43: 5260797070 | H43: 57108359715 | I43: 3431279650 | J43: 90.75
F44: Eurocash | G44: =933519.41*1000 -> 933519410 | H44: 917086055 | I44: 3841230 | J44: 6.58
D49: LTM 2025 | E49: 2026 | F49: 2027 | G49: 2028 | H49: 2029 | I49: 2030
C50: Przychody ze sprzedaży | D50: 32490.262 | E50: 33372.123 | F50: 37643.755 | G50: 41972.786 | H50: 46128.092 | I50: 50002.852
C51: Zysk operacyjny (EBIT) | D51: 2085.198 | E51: 2169.188 | F51: 2409.2003 | G51: 2602.3128 | H51: 2813.8136 | I51: 3050.174
C52: Marża EBIT | D52: 0.064179169 | E52: 0.065 | F52: 0.064 | G52: 0.062 | H52: 0.061 | I52: 0.061

Sheet RZIS_2
A1: Rachunek zysków i strat | B1: 2024 | C1: 2023 | D1: 2022 | E1: 2021 | F1: 2020
A2: I. Przychody ze sprzedaży | B2: 29273792 | C2: 25666255 | D2: 19801622 | E2: 13362012 | F2: 10125815
A3: II. Koszt własny sprzedaży | B3: 22463233 | C3: 19741459 | D3: 15038630 | E3: 10038342 | F3: 7521986
A4: III. Zysk/strata brutto ze sprzedaży | B4: 6810559 | C4: 5924796 | D4: 4762992 | E4: 3323670 | F4: 2603829
A5: IV. Koszty sprzedaży | B5: 4678717 | C5: 3878421 | D5: 3080061 | E5: 2181963 | F5: 1668084
A6: V. Koszty ogólnego zarządu | B6: 233653 | C6: 173736 | D6: 143217 | E6: 117285 | F6: 99783
A7: VIII. Pozostałe przychody operacyjne | B7: 24185 | C7: 13477 | D7: 16282 | E7: 14364 | F7: 7598
A8: IX. Pozostałe koszty operacyjne | B8: 14044 | C8: 10261 | D8: 18177 | E8: 14793 | F8: 5701
A9: XI. Zysk/strata na działalności operacyjnej | B9: 1908330 | C9: 1875855 | D9: 1537819 | E9: 1023993 | F9: 837859
A10: XII. Przychody finansowe | B10: 6657 | C10: 10442 | D10: 5092 | E10: 1119 | F10: 3237
A11: XIII. Koszty finansowe | B11: 121424 | C11: 147316 | D11: 141293 | E11: 46703 | F11: 52096
A12: XVIII. Zysk/strata brutto | B12: 1793563 | C12: 1738981 | D12: 1401618 | E12: 978409 | F12: 789000
A13: XIX. Podatek dochodowy | B13: -287834 | C13: -333654 | D13: -269531 | E13: -173106 | F13: -145083
A14: XXII. Zysk/strata netto z działalności kontynuowanej | E14: 805303 | F14: 643917
A15: XXIV. Zysk/strata netto | B15: 1505729 | C15: 1405327 | D15: 1132087 | E15: 805303 | F15: 643917
A16: 1. zysk/strata netto udziałowców jednostki dominującej | B16: 1504980 | C16: 1405327 | D16: 1132087 | E16: 805303 | F16: 643917
A17: 2. zysk/strata netto właścicieli udziałów niekontrolujących | B17: 749
A18: - Amortyzacja (noty) | B18: 409179 | C18: 356828 | D18: 300129 | E18: 247343 | F18: 198146
A20: Bilans | B20: 2024 | C20: 2023 | D20: 2022 | E20: 2021 | F20: 2020
A21: AKTYWA | B21: 13055794 | C21: 10377715 | D21: 9003059 | E21: 7168531 | F21: 5570510
A22: I. Aktywa trwałe | B22: 8616378 | C22: 7124550 | D22: 6296353 | E22: 5183347 | F22: 4053812
A23: 1. Rzeczowe aktywa trwałe | B23: 8230915 | C23: 6874672 | D23: 6070032 | E23: 4911353 | F23: 3749480
A24: 3. Wartości niematerialne | B24: 169964 | C24: 115056 | D24: 94737 | E24: 96947 | F24: 99050
A25: 9. Aktywa z tytułu odroczonego podatku dochodowego | B25: 74149 | C25: 41323 | D25: 26468 | E25: 35116 | F25: 20738
A26: 12. Pozostałe aktywa długoterminowe | B26: 141350 | C26: 93499 | D26: 105116 | E26: 139931 | F26: 184544
A27: II. Aktywa obrotowe | B27: 4439416 | C27: 3253165 | D27: 2706706 | E27: 1985184 | F27: 1516698
A28: 1. Zapasy | B28: 3081444 | C28: 2638859 | D28: 1978778 | E28: 1373463 | F28: 875147
A29: 3. Należności handlowe | D29: 274872 | E29: 144012 | F29: 86822
A30: 4. Pożyczki i pozostałe należności | B30: 376700 | C30: 330492 | E30: 55 | F30: 2
A31: 5. Aktywa finansowe | B31: 2064 | C31: 1376 | D31: 1242 | E31: 1327 | F31: 942
A32: 6. Środki pieniężne i ich ekwiwalenty | B32: 891022 | C32: 218389 | D32: 382718 | E32: 418615 | F32: 480418
A33: 10. Pozostałe aktywa | B33: 88186 | C33: 64049 | D33: 69096 | E33: 47712 | F33: 73367
A34: PASYWA | B34: 13055794 | C34: 10377715 | D34: 9003059 | E34: 7168531 | F34: 5570510
A35: I. Kapitał własny udziałowców podmiotu dominującego | B35: 7102434 | C35: 5605311 | D35: 4203783 | E35: 3070190 | F35: 2266563
A36: 1. Kapitał podstawowy | B36: 9804 | C36: 9804 | D36: 9804 | E36: 9804 | F36: 9804
A37: 4. Kapitał zapasowy | B37: 6058912 | C37: 4652148 | D37: 3512022 | E37: 2707720 | F37: 2063322
A38: 6. Pozostałe kapitały | B38: -15436 | C38: 7500 | D38: 7500 | E38: 7500 | F38: 7500
A39: 7. Zyski zatrzymane / niepokryte straty | B39: 1031871 | C39: 935859 | D39: 674457 | E39: 345166 | F39: 185937
A40: II. Udziały niekontrolujące | B40: 17283
A41: III. Zobowiązania długoterminowe | B41: 570511 | C41: 893111 | D41: 1109149 | E41: 1092804 | F41: 2266563
...

Sheet Kd
B11: 2024 | C11: 2023 | D11: 2022 | E11: 2021 | F11: 2020 | H11: 2025Q3
A12: 2. Długoterminowe zobowiązania finansowe | B12: 170000 | C12: 370000 | D12: 370000 | E12: 450000 | F12: 419936
A13: 3. Długoterminowe kredyty i pożyczki | B13: 272219 | C13: 469629 | D13: 690862 | E13: 583014 | F13: 725851 | H13: 224261
A14: 11. Długoterminowe zobowiązania z tytułu leasingu | B14: 60818 | C14: 35612 | D14: 34673 | E14: 46621 | F14: 67876 | H14: 74581
A15: Long term debt | B15: =SUM(B12:B14)/1000 -> 503.037 | C15: =SUM(C12:C14)/1000 -> 875.241 | D15: =SUM(D12:D14)/1000 -> 1095.535 | E15: =SUM(E12:E14)/1000 -> 1079.635 | F15: =SUM(F12:F14)/1000 -> 1213.663 | H15: =SUM(H13:H14)/1000 -> 298.842
A17: 2. Zobowiązania finansowe | B17: 204845 | C17: 4784 | D17: 260947 | E17: 171642 | F17: 930 | H17: 374432
A18: 3. Krótkoterminowe kredyty i pożyczki | B18: 361034 | C18: 278588 | D18: 410157 | E18: 196169 | F18: 216868 | H18: 168597
A19: 4. Krótkoterminowe zobowiązania z tytułu leasingu | B19: 17900 | C19: 14565 | D19: 17893 | E19: 27721 | F19: 42249 | H19: 15603
A20: Loans & short-term debt | B20: =SUM(B17:B19)/1000 -> 583.779 | C20: =SUM(C17:C19)/1000 -> 297.937 | D20: =SUM(D17:D19)/1000 -> 688.997 | E20: =SUM(E17:E19)/1000 -> 395.532 | F20: =SUM(F17:F19)/1000 -> 260.047 | H20: =SUM(H17:H19)/1000 -> 558.632
A22: suma długu | B22: =B15+B20 -> 1086.816 | C22: =C15+C20 -> 1173.178 | D22: =D15+D20 -> 1784.532 | E22: =E15+E20 -> 1475.167 | F22: =F15+F20 -> 1473.71 | H22: =SUM(H20,H15) -> 857.474
A23: 10. Odsetki z działalności finansowej | B23: =121292/1000 -> 121.292 | C23: =148974/1000 -> 148.974 | D23: =129062/1000 -> 129.062 | E23: =46645/1000 -> 46.645 | F23: =52012/1000 -> 52.012
A24: koszt długu | B24: =B23/B22 -> 0.11160307 | C24: =C23/C22 -> 0.12698329 | D24: =D23/D22 -> 0.072322603 | E24: =E23/E22 -> 0.031620149 | F24: =F23/F22 -> 0.03529324
A27: środki pieniężne i ekwiwalenty | H27: 574.917
A28: Dług netto | H28: =H22-H27 -> 282.557

Sheet Summary
B1: Wszystkie wartości pieniężne wyrażone są w mln PLN, z wyjątkiem kursu akcji oraz wyceny na akcję (PLN)
B2: Dino Polska S.A. | C2: Wycena DCF | D2: Kurs rynkowy (Luty 2026) | E2: Potencjał (Upside/Downside) | F2: Główne źródła rozbieżności:
B3: Rekomendacja: SPRZEDAJ | C3: =Valuation!B34 -> 29.25336 | D3: 39.63 | E3: =(C3-D3)/D3 -> -0.261838 | F3: Bardzo wysokie założenia wzrostu (g): Rynek wycenia Dino przy założeniu, że spółka będzie rosła w nieskończoność o ponad 3,5-4,0% rocznie. Moja wycena opiera się na konserwatywnym i bezpiecznym g=2,5%, co jest spójne z długoterminowym celem inflacyjnym NBP.
B6: Pozycja (mln PLN) | C6: LTM (-2025Q3) | D6: 2030E | E6: Zmiana (%)
B7: Przychody ze sprzedaży | C7: =Historicals!G3 -> 32490.262 | D7: =Forecast!G6 -> 50002.852 | E7: =(D7-C7)/C7 -> 0.53901043
B8: Wynik operacyjny (EBIT) | C8: =Historicals!G4 -> 2085.198 | D8: =Forecast!G8 -> 3050.174 | E8: =(D8-C8)/C8 -> 0.46277426 | F8: Niedoszacowanie ryzyk operacyjnych: Kurs giełdowy wydaje się ignorować strukturalny spadek marż operacyjnych (z 8,3% w 2022 r. do 6,4% obecnie), zakładając powrót do historycznie wysokich rentowności, co przy obecnych kosztach pracy jest mało prawdopodobne.
B9: Marża EBIT (%) | C9: =Historicals!G10 -> 0.064179169 | D9: =Forecast!G7 -> 0.061 | E9: =TEXT((D9-C9)*100,"0,00")&" p.p" -> -0,32 p.p
B10: Wolne przepływy (FCFF) | C10: =Historicals!G15 -> 224.41838 | D10: =Forecast!G18 -> 720.5411 | E10: =(D10-C10)/C10 -> 2.2107045
F13: Premia za „Growth Darling”: Inwestorzy płacą za Dino „premię za jakość i wzrost”, która odrywa cenę od fundamentów gotówkowych. Z perspektywy stopy zwrotu, przy cenie 39,63 PLN inwestor akceptuje IRR na poziomie 2,3%, co jest nieuzasadnione przy dostępności obligacji skarbowych oferujących 4,5%
G19: Cena akcji
G20: WACC \ g | H20: 0.02 | I20: 0.025 | J20: 0.03
G21: 0.075 | H21: 31.199921 | I21: 34.365121 | J21: 38.233697
G22: 0.0836 | H22: 26.928881 | I22: 29.264376 | J22: 32.035599
G23: 0.09 | H23: 24.432864 | I23: 26.345896 | J23: 28.577767
G24: Aby uzasadnić obecną cenę rynkową (~40 PLN), rynek musiałby zakładać np. spadek WACC poniżej 7,5% lub wzrost g powyżej 3,0%.
B27: Spółka | C27: P/E (Cena/Zysk) | D27: EV/EBITDA
B28: Dino Polska S.A. (przy 29,25 PLN) | C28: =PRODUCT(Valuation!B33:B34)/RZiS!I42 -> 24.079649 | D28: =PRODUCT(Valuation!B33:B34)/RZiS!G42 -> 18.33812
B29: Dino Polska S.A. (przy 39,63 PLN) | C29: =RZiS!H42/RZiS!I42 -> 32.398842 | D29: =RZiS!H42/RZiS!G42 -> 24.673692
B30: Jeronimo Martins Polska S.A. | C30: =RZiS!H43/RZiS!I43 -> 16.643458 | D30: =RZiS!H43/RZiS!G43 -> 10.855458
B31: Eurocash S.A.* | C31: -32.04 | D31: 6.6
D33: Kluczowe Ryzyka Inwestycyjne
B34: Presja kosztowa i marżowa: Dalszy gwałtowny wzrost kosztów pracy oraz cen energii stanowi bezpośrednie zagrożenie dla założonej marży EBIT (prognozowanej na poziomie 6,1% w 2030E)
B36: Intensyfikacja wojen cenowych: Agresywna walka o klienta pomiędzy liderami rynku (Biedronka, Lidl) może zmusić Dino do obniżenia marż handlowych, by zachować konkurencyjność cenową.
B38: Ryzyko nasycenia i ekspansji: Zakładana kontynuacja ekspansji na ścianie wschodniej wiąże się z niższym nasyceniem, ale też niższą siłą nabywczą konsumentów, co może spowolnić dynamikę sprzedaży Like-for-Like (LFL).
B40: Normalizacja mnożników rynkowych: Obecna wycena rynkowa (P/E 32,4) zakłada utrzymanie ogromnej premii względem konkurentów takich jak Jeronimo Martins (P/E 16,6). Każde rozczarowanie wynikami może doprowadzić do gwałtownej korekty mnożników.

Sheet Historicals
A1: Wszystkie wartości pieniężne wyrażone są w mln PLN, z wyjątkiem kursu akcji oraz wyceny na akcję (PLN)
A2: Pozycja (mln PLN) | B2: 2020 | C2: 2021 | D2: 2022 | E2: 2023 | F2: 2024 | G2: LTM
A3: Przychody ze sprzedaży | B3: 10125.815 | C3: 13362.012 | D3: 19801.622 | E3: 25666.255 | F3: 29273.792 | G3: 32490.262
A4: Zysk operacyjny (EBIT) | B4: 837.859 | C4: 1023.993 | D4: 1537.819 | E4: 1875.855 | F4: 1908.33 | G4: 2085.198
A5: Stawka podatku dochodowego | B5: 0.19 | C5: 0.19 | D5: 0.19 | E5: 0.19 | F5: 0.19 | G5: 0.19
A6: NOPAT | B6: =B4*(1-B5) -> 678.66579 | C6: =C4*(1-C5) -> 829.43433 | D6: =D4*(1-D5) -> 1245.6334 | E6: =E4*(1-E5) -> 1519.4426 | F6: =F4*(1-F5) -> 1545.7473 | G6: =G4*(1-G5) -> 1689.0104
A7: Amortyzacja (D&A) | B7: 198.146 | C7: 247.343 | D7: 300.129 | E7: 356.828 | F7: 409.179 | G7: 479.009
A8: CAPEX (niematerialne i rzeczowe) | B8: 1002.025 | C8: 1335.604 | D8: 1445.905 | E8: 1172.863 | F8: 1561.914 | G8: 2007.18
A9: Zmiana kapitału obrotowego (NWC) | B9: 83.377 | C9: -219.986 | D9: 199.047 | E9: 629.481 | F9: -646.263 | G9: -63.579
A10: Marża EBIT | B10: =B4/B3 -> 0.082744846 | C10: =C4/C3 -> 0.076634642 | D10: =D4/D3 -> 0.077661264 | E10: =E4/E3 -> 0.073086432 | F10: =F4/F3 -> 0.065189026 | G10: =G4/G3 -> 0.064179169
A11: CAPEX do przychodów ze sprzedaży | B11: =B8/B3 -> 0.098957467 | C11: =C8/C3 -> 0.099955306 | D11: =D8/D3 -> 0.073019523 | E11: =E8/E3 -> 0.045696694 | F11: =F8/F3 -> 0.05335537 | G11: =G8/G3 -> 0.061777895
A12: Wzrost sprzedaży r/r | C12: =C3/B3-1 -> 0.31959867 | D12: =D3/C3-1 -> 0.48193416 | E12: =E3/D3-1 -> 0.29616932 | F12: =F3/E3-1 -> 0.14055564 | G12: 0.149
A13: Amortyzacja do przychodów ze sprzedaży | B13: =B7/B3 -> 0.0195684 | C13: =C7/C3 -> 0.01851091 | D13: =D7/D3 -> 0.015156789 | E13: =E7/E3 -> 0.013902613 | F13: =F7/F3 -> 0.013977656 | G13: =G7/G3 -> 0.014743156
A14: Zmiana NWC do przychodów ze sprzedaży | B14: =B9/B3 -> 0.0082341026 | C14: =C9/C3 -> -0.016463539 | D14: =D9/D3 -> 0.010052055 | E14: =E9/E3 -> 0.024525627 | F14: =F9/F3 -> -0.022076504 | G14: =G9/G3 -> -0.0019568633
A15: FCFF | B15: =B6+B7-B8-B9 -> -208.59021 | C15: =C6+C7-C8-C9 -> -38.84067 | D15: =D6+D7-D8-D9 -> -99.18961 | E15: =E6+E7-E8-E9 -> 73.92655 | F15: =F6+F7-F8-F9 -> 1039.2753 | G15: =G6+G7-G8-G9 -> 224.41838

Sheet Assumptions
A1: Wszystkie wartości pieniężne wyrażone są w mln PLN, z wyjątkiem kursu akcji oraz wyceny na akcję (PLN)
A2: Parametr | B2: Założona wartość | G2: Uzasadnienie | H2: Źródło / Referencja
B3: 2026E | C3: 2027E | D3: 2028E | E3: 2029E | F3: 2030E
A4: Wzrost sprzedaży r/r | B4: 0.14 | C4: 0.128 | D4: 0.115 | E4: 0.099 | F4: 0.084 | G4: Kontynuacja ekspansji geograficznej (głównie ściana wschodnia). Zakładana malejąca dynamika wynika z rosnącego nasycenia rynku w regionach o najwyższej obecności sieci. | H4: Raport roczny 2024 własne
A5: Marża EBIT | B5: 0.065 | C5: 0.064 | D5: 0.062 | E5: 0.061 | F5: 0.061 | G5: Konserwatywne założenie lekkiej kompresji marży ze względu na presję kosztową (koszty pracy) oraz intensywną konkurencję cenową w sektorze. | H5: emis.com własne
A6: Efektywna stawka podatkowa | B6: 0.19 | C6: 0.19 | D6: 0.19 | E6: 0.19 | F6: 0.19 | G6: Przyjęcie stawki ustawowej 19% w oparciu o wysoką stabilność historyczną efektywnej stopy podatkowej (ETR) spółki. | H6: emis.com własne
A7: CAPEX / Przychody ze sprzedaży | B7: 0.064 | C7: 0.06 | D7: 0.057 | E7: 0.054 | F7: 0.05 | G7: Utrzymanie wysokiego tempa inwestycji w sieć i logistykę zgodnie ze strategią. Spadek wskaźnika % wynika z efektu skali (szybszy wzrost bazy przychodowej względem nakładów). | H7: grupadino.pl/faq Raport roczny 2024 własne
A8: Amortyzacja do przychodów ze sprzedaży | B8: 0.015 | C8: 0.015 | D8: 0.015 | E8: 0.015 | F8: 0.015 | G8: Stabilizacja wskaźnika na poziomie historycznym, odzwierciedlająca regularny cykl zużycia majątku trwałego sieci. | H8: biznesradar.pl własne
A9: Zmiana NWC do przychodów ze sprzedaży | B9: 0 | C9: 0 | D9: 0 | E9: 0 | F9: 0 | G9: Założenie neutralnego wpływu kapitału obrotowego na FCF, oparte na średniej z poprzednich okresów sprawozdawczych. | H9: emis.com własne
A10: Stopa wolna od ryzyka (Rf) | B10: 0.045 | C10: 0.043 | D10: 0.04 | E10: 0.04 | F10: 0.04 | G10: Oparta na prognozach rentowności 10-letnich obligacji skarbowych z założeniem stabilizacji w okolicach 4,0%. | H10: pekao.com.pl/analizy-makroekonomiczne/tabela-prognoz/ własne
A11: Beta | B11: 0.74 | C11: 0.74 | D11: 0.74 | E11: 0.74 | F11: 0.74 | G11: Wartość 0,74 odzwierciedla defensywny charakter sektora spożywczego i wysoką odporność modelu biznesowego Dino na wahania cyklu koniunkturalnego. | H11: emis.com
A12: Premia za ryzyko rynkowe (ERP) | B12: 0.06 | C12: 0.06 | D12: 0.06 | E12: 0.06 | F12: 0.06 | G12: Przyjęto 6,0% jako konserwatywny kompromis między aktualną premią implikowaną (Damodaran) a historycznym standardem polskiego rynku. | H12: Damodaran własne
A13: Koszt długu przed opodatkowaniemt długu | B13: 0.065 | C13: 0.063 | D13: 0.06 | E13: 0.06 | F13: 0.06 | G13: Wartość oparta na aktualnej stopie referencyjnej WIBOR 3M powiększonej o marżę kredytową oraz efektywny koszt leasingu operacyjnego. W następnych latach przewiduje spadek WIBOR 3M. | H13: własne
A14: Koszt długu uwzględniający tarczę podatkową | B14: =(1-0.19)*B13 -> 0.05265 | C14: =(1-0.19)*C13 -> 0.05103 | D14: =(1-0.19)*D13 -> 0.0486 | E14: =(1-0.19)*E13 -> 0.0486 | F14: =(1-0.19)*F13 -> 0.0486
A15: Stopa Wzrostu po Prognozie (g) | B15: 0.025 | G15: Przyjęto wartość zbieżną z długoterminowym celem inflacyjnym NBP. | H15: własne
A16: Terminal CAPEX / Przychody | B16: 0.017 | G16: Poziom 1,7% odzwierciedla konwergencję nakładów inwestycyjnych do poziomu amortyzacji po okresie intensywnej ekspansji. | H16: własne

Sheet Forecast
A1: Wszystkie wartości pieniężne wyrażone są w mln PLN, z wyjątkiem kursu akcji oraz wyceny na akcję (PLN)
A2: Przychody ze sprzedaży z 2024r | B2: =Historicals!F3 -> 29273.792
A4: Parametr | B4: LTM | C4: 2026E | D4: 2027E | E4: 2028E | F4: 2029E | G4: 2030E
A5: Wzrost sprzedaży r/r | B5: =Historicals!G12 -> 0.149 | C5: =Assumptions!B4 -> 0.14 | D5: =Assumptions!C4 -> 0.128 | E5: =Assumptions!D4 -> 0.115 | F5: =Assumptions!E4 -> 0.099 | G5: =Assumptions!F4 -> 0.084
A6: Przychody ze sprzedaży | B6: =Historicals!G3 -> 32490.262 | C6: =B2*(1+C5) -> 33372.123 | D6: =C6*(1+D5) -> 37643.755 | E6: =D6*(1+E5) -> 41972.786 | F6: =E6*(1+F5) -> 46128.092 | G6: =F6*(1+G5) -> 50002.852
A7: Marża EBIT | B7: =Historicals!G10 -> 0.064179169 | C7: =Assumptions!B5 -> 0.065 | D7: =Assumptions!C5 -> 0.064 | E7: =Assumptions!D5 -> 0.062 | F7: =Assumptions!E5 -> 0.061 | G7: =Assumptions!F5 -> 0.061
A8: Zysk operacyjny (EBIT) | B8: =Historicals!G4 -> 2085.198 | C8: =C6*C7 -> 2169.188 | D8: =D6*D7 -> 2409.2003 | E8: =E6*E7 -> 2602.3128 | F8: =F6*F7 -> 2813.8136 | G8: =G6*G7 -> 3050.174
A9: Efektywna stawka podatkowa | B9: =Historicals!G5 -> 0.19 | C9: =Assumptions!B6 -> 0.19 | D9: =Assumptions!C6 -> 0.19 | E9: =Assumptions!D6 -> 0.19 | F9: =Assumptions!E6 -> 0.19 | G9: =Assumptions!F6 -> 0.19
A10: Podatek dochodowy | B10: =B9*B8 -> 396.18762 | C10: =C9*C8 -> 412.14572 | D10: =D9*D8 -> 457.74806 | E10: =E9*E8 -> 494.43942 | F10: =F9*F8 -> 534.62459 | G10: =G9*G8 -> 579.53305
A11: NOPAT | B11: =Historicals!G6 -> 1689.0104 | C11: =C8-C10 -> 1757.0423 | D11: =D8-D10 -> 1951.4522 | E11: =E8-E10 -> 2107.8733 | F11: =F8-F10 -> 2279.189 | G11: =G8-G10 -> 2470.6409
A12: Amortyzacja do przychodów ze sprzedaży | B12: =Historicals!G13 -> 0.014743156 | C12: =Assumptions!B8 -> 0.015 | D12: =Assumptions!C8 -> 0.015 | E12: =Assumptions!D8 -> 0.015 | F12: =Assumptions!E8 -> 0.015 | G12: =Assumptions!F8 -> 0.015
A13: Amortyzacja (D&A) | B13: =Historicals!G7 -> 479.009 | C13: =C12*C6 -> 500.58184 | D13: =D12*D6 -> 564.65632 | E13: =E12*E6 -> 629.5918 | F13: =F12*F6 -> 691.92138 | G13: =G12*G6 -> 750.04278
A14: CAPEX do przychodów ze sprzedaży | B14: =Historicals!G11 -> 0.061777895 | C14: =Assumptions!B7 -> 0.064 | D14: =Assumptions!C7 -> 0.06 | E14: =Assumptions!D7 -> 0.057 | F14: =Assumptions!E7 -> 0.054 | G14: =Assumptions!F7 -> 0.05
A15: CAPEX | B15: =Historicals!G8 -> 2007.18 | C15: =C14*C6 -> 2135.8159 | D15: =D14*D6 -> 2258.6253 | E15: =E14*E6 -> 2392.4488 | F15: =F14*F6 -> 2490.917 | G15: =G14*G6 -> 2500.1426
A16: Zmiana NWC do przychodów ze sprzedaży | B16: =Historicals!G14 -> -0.0019568633 | C16: =Assumptions!B9 -> 0 | D16: =Assumptions!C9 -> 0 | E16: =Assumptions!D9 -> 0 | F16: =Assumptions!E9 -> 0 | G16: =Assumptions!F9 -> 0
A17: Zmiana NWC | B17: =Historicals!G9 -> -63.579 | C17: =C16*C6 -> 0 | D17: =D16*D6 -> 0 | E17: =E16*E6 -> 0 | F17: =F16*F6 -> 0 | G17: =G16*G6 -> 0
A18: FCFF | B18: =B11+B13-B15-B17 -> 224.41838 | C18: =C11+C13-C15-C17 -> 121.80825 | D18: =D11+D13-D15-D17 -> 257.48328 | E18: =E11+E13-E15-E17 -> 345.0163 | F18: =F11+F13-F15-F17 -> 480.19344 | G18: =G11+G13-G15-G17 -> 720.5411

Sheet Valuation
A1: Wszystkie wartości pieniężne wyrażone są w mln PLN, z wyjątkiem kursu akcji oraz wyceny na akcję (PLN)
A2: Cena akcji | B2: 39.63 | C2: Struktura kapitału Dino Polska opiera się w przeważającej mierze na kapitale własnym (We​≈97,8%), co wynika z wysokiej kapitalizacji rynkowej oraz zdolności spółki do samofinansowania ekspansji operacyjnej. Tak niski poziom dźwigni finansowej (Wd​=2,2%) minimalizuje ryzyko finansowe i czyni wycenę DCF bardziej odporną na wahania rynkowych stóp procentowych.
A3: Kapitalizacja rynkowa | B3: 38588.544
A4: Suma długu 2025Q3 | B4: 857.474
A5: Wartość przedsiębiorstwa | B5: =SUM(B3:B4) -> 39446.018
A6: Wd | B6: =B4/B5 -> 0.02173791
A7: We | B7: =B3/B5 -> 0.97826209
B9: 2026E | C9: 2027E | D9: 2028E | E9: 2029E | F9: 2030E
A10: Stopa wolna od ryzyka (Rf) | B10: =Assumptions!B10 -> 0.045 | C10: =Assumptions!C10 -> 0.043 | D10: =Assumptions!D10 -> 0.04 | E10: =Assumptions!E10 -> 0.04 | F10: =Assumptions!F10 -> 0.04
A11: Beta | B11: =Assumptions!B11 -> 0.74 | C11: =Assumptions!C11 -> 0.74 | D11: =Assumptions!D11 -> 0.74 | E11: =Assumptions!E11 -> 0.74 | F11: =Assumptions!F11 -> 0.74
A12: Premia za ryzyko rynkowe (ERP) | B12: =Assumptions!B12 -> 0.06 | C12: =Assumptions!C12 -> 0.06 | D12: =Assumptions!D12 -> 0.06 | E12: =Assumptions!E12 -> 0.06 | F12: =Assumptions!F12 -> 0.06 | G12: Koszt kapitału własnego obliczony zgodnie z modelem CAPM: Ke​=Rf​+β×ERP
A13: Ke | B13: =B10+B11*B12 -> 0.0894 | C13: =C10+C11*C12 -> 0.0874 | D13: =D10+D11*D12 -> 0.0844 | E13: =E10+E11*E12 -> 0.0844 | F13: =F10+F11*F12 -> 0.0844
A14: Koszt długu uwzględniający tarczę podatkową | B14: =Assumptions!B14 -> 0.05265 | C14: =Assumptions!C14 -> 0.05103 | D14: =Assumptions!D14 -> 0.0486 | E14: =Assumptions!E14 -> 0.0486 | F14: =Assumptions!F14 -> 0.0486
A15: WACC | B15: =B13*$B$7+$B$6*B14 -> 0.088601132 | C15: =C13*$B$7+$B$6*C14 -> 0.086609392 | D15: =D13*$B$7+$B$6*D14 -> 0.083621783 | E15: =E13*$B$7+$B$6*E14 -> 0.083621783 | F15: =F13*$B$7+$B$6*F14 -> 0.083621783
A17: FCFF | B17: =Forecast!C18 -> 121.80825 | C17: =Forecast!D18 -> 257.48328 | D17: =Forecast!E18 -> 345.0163 | E17: =Forecast!F18 -> 480.19344 | F17: =Forecast!G18 -> 720.5411
A18: PV | B18: {=B17/PRODUCT(1+$B$15:B15)} -> 111.89429 | C18: {=C17/PRODUCT(1+$B$15:C15)} -> 217.67412 | D18: {=D17/PRODUCT(1+$B$15:D15)} -> 269.16566 | E18: {=E17/PRODUCT(1+$B$15:E15)} -> 345.71525 | F18: {=F17/PRODUCT(1+$B$15:F15)} -> 478.72195
A20: Stopa Wzrostu po Prognozie (g) | B20: =Assumptions!B15 -> 0.025
A21: Terminal CAPEX / Przychody | B21: =Assumptions!B16 -> 0.017
A22: NOPAT 2030E | B22: =Forecast!G11 -> 2470.6409
A23: Amortyzacja 2030E | B23: =Forecast!G13 -> 750.04278
A24: Terminal CAPEX | B24: =Forecast!G6*Valuation!B21 -> 850.04848
A25: Zmiana NWC | B25: =Forecast!G17 -> 0
A26: Normalizowane FCFF | B26: =B22+B23-B24-B25 -> 2370.6352
A28: Wartość rezydualna (TV) | B28: =B26*(1+B20)/(Valuation!F15-B20) -> 41450.481
A29: PV(TV) | B29: {=B28/PRODUCT(1+B15:F15)} -> 27539.38
A30: Wartość przedsiębiorstwa (EV) | B30: =SUM(B18:F18)+B29 -> 28962.551
A31: Dług netto (2025Q3) | B31: 282.557
A32: Wartość Kapitału Własnego | B32: =B30-B31 -> 28679.994
A33: Liczba akcji | B33: 980400000
A34: Wartość na akcje | B34: =B32*1000000/B33 -> 29.25336
A37: Analiza wrażliwości
B38: Stopa Wzrostu po Prognozie (g)
A39: WACC | B39: =B34 -> 29.25336 | C39: 0.015 | D39: 0.02 | E39: 0.025 | F39: 0.03 | G39: 0.035 | H39: 0.04
B40: 0.07 | C40: 31.194654 | D40: 34.359853 | E40: 38.22843 | F40: 43.064151 | G40: 49.281507 | H40: 57.571314
B41: 0.075 | C41: 28.562255 | D41: 31.199921 | E41: 34.365121 | F41: 38.233697 | G41: 43.069418 | H41: 49.286774
B42: 0.08 | C42: 26.335603 | D42: 28.567474 | E42: 31.20514 | F42: 34.370339 | G42: 38.238916 | H42: 43.074637
B43: 0.0836 | C43: 24.933837 | D43: 26.928881 | E43: 29.264376 | F43: 32.035599 | G43: 35.377031 | H43: 39.484847
B44: 0.09 | C44: 22.774902 | D44: 24.432864 | E44: 26.345896 | F44: 28.577767 | G44: 31.215433 | H44: 34.380632
B45: 0.095 | C45: 21.329262 | D45: 22.779978 | E45: 24.43794 | F45: 26.350972 | G45: 28.582843 | H45: 31.220509
A48: Wewnętrzna stopa zwrotu (IRR)
...
